Workbook

Sheet 2
I2: CHAPITRE
I4: 2
B9: LES COLLECTIVITÉS
B10: LOCALES
B11: ET LEUR POPULATION
B14: Présentation - Définitions
B16: 2-1 Le découpage administratif de la République et sa population
B18: 2-2 Le nombre de collectivités territoriales
B20: 2-3a Les communes par taille : nombre et population
B22: 2-3b Les communes par taille : répartitions en %
B24: 2-4 Les communes de plus de 100 000 habitants
B26: 2-5a Les groupements de collectivités territoriales
B28: 2-5b Les groupements de collectivités territoriales : carte de l'intercommunalité à fiscalité propre au 1er janvier 2026
B30: 2-6 Les groupements de communes à fiscalité propre par taille
... B36: 2-7c Les principaux groupements de communes à fiscalité propre : communautés de communes

Sheet 2.1
A1: 2.1 Le découpage administratif de la République et sa population
A2: Le découpage administratif de la République
A3: (en nombre)
B4: 2022 | C4: 2023 | D4: 2024 | E4: 2025 | F4: 2026
A5: Communes | B5: 35038 | C5: 35028 | D5: 35018 | E5: 34958 | F5: 34958
A6: dont : France métropolitaine | B6: 34826 | C6: 34816 | D6: 34806 | E6: 34746 | F6: 34746
A7: DOM | B7: 129 | C7: 129 | D7: 129 | E7: 129 | F7: 129
A8: COM et Nouvelle-Calédonie (a) | B8: 83 | C8: 83 | D8: 83 | E8: 83 | F8: 83
A10: Arrondissements (sudivisions des départements) | B10: 332 | C10: 333 | D10: 333 | E10: 333 | F10: 333
A11: dont : France métropolitaine | B11: 320 | C11: 320 | D11: 320 | E11: 320 | F11: 320
A12: DOM | B12: 12 | C12: 13 | D12: 13 | E12: 13 | F12: 13
A14: Départements (à distinguer des Conseils départementaux) | B14: 101 | C14: 101 | D14: 101 | E14: 101 | F14: 101
A15: dont : France métropolitaine | B15: 96 | C15: 96 | D15: 96 | E15: 96 | F15: 96
A16: DOM | B16: 5 | C16: 5 | D16: 5 | E16: 5 | F16: 5
A18: Régions (à distinguer des Conseils régionaux) | B18: 18 | C18: 18 | D18: 18 | E18: 18 | F18: 18
A19: dont : France métropolitaine | B19: 13 | C19: 13 | D19: 13 | E19: 13 | F19: 13
... A22: Collectivités d'outre-mer, TAAF et Nouvelle Calédonie (a) | B22: 8 | C22: 8 | D22: 8 | E22: 8 | F22: 8
A23: Source : Insee, Code officiel géographique.
A24: (a) St-Pierre-et-Miquelon (2 communes) ; Saint Barthélémy ; Saint Martin ; Polynésie française (48 communes). Nouvelle-Calédonie (33 communes). Wallis et Futuna (Territoire, découpé en trois circonscriptions territoriales). Terres australes et antarctiques françaises (TAAF, sans population), découpées en cinq districts. Île de Clipperton (sans population), rattachée directement au gouvernement.
A26: Population municipale
A27: (en nombre d'habitants)
A28: Au 1er janvier | B28: 2022 | C28: 2023 | D28: 2024 | E28: 2025 | F28: 2026
A29: France métropolitaine et d'outre-mer | B29: 67244921 | C29: 67418672 | D29: 67664570 | E29: 68017091 | F29: 68350798
A30: dont : France métropolitaine | B30: 65096768 | C30: 65269154 | D30: 65505213 | E30: 65846255 | F30: 66165815
A31: DOM | B31: 2148153 | C31: 2149518 | D31: 2159357 | E31: 2170836 | F31: 2184983
A32: Collectivités d'outre-mer et Nouvelle-Calédonie
A33: Saint-Pierre-et-Miquelon | B33: 5974 | C33: 5925 | D33: 5873 | E33: 5819 | F33: 5790
A34: Saint-Barthélémy | B34: 10289 | C34: 10457 | D34: 10464 | E34: 10562 | F34: 10660
A35: Saint-Martin | B35: 32489 | C35: 31801 | D35: 31477 | E35: 31496 | F35: 31160
A36: Polynésie française (recensements 2017 et 2022) | B36: 278786 | C36: 278786 | D36: 278786 | E36: 278786 | F36: 278786
A37: Wallis-et-Futuna (dernier recensement en 2023) | B37: 11558 | C37: 11558 | D37: 11151 | E37: 11151 | F37: 11151
A38: Nouvelle-Calédonie (dernier recensement en 2025) | B38: 271407 | C38: 271407 | D38: 271407 | E38: 271407 | F38: 264596
A39: Ensemble République française | B39: 67852556 | C39: 68025738 | D39: 68273728 | E39: 68626312 | F39: =SUM(F30:F38) -> 68952941
A40: Source : Insee, Recensement de la population. Population municipale en vigueur en année N (millésimée année N-3)

Sheet 2.2 nb CL
A1: 2.2 Le nombre de collectivités locales
A2: Les collectivités territoriales en France métropolitaine et dans les départements d'outre-mer
A3: (en nombre de collectivités)
B5: 2022 | C5: 2023 | D5: 2024 | E5: 2025 | F5: 2026
A6: Ensemble des collectivités locales | B6: 45205 | C6: 45090 | D6: 44932 | E6: 44565 | F6: 44354
A7: Collectivité territoriales | B7: 35069 | C7: 35059 | D7: 35049 | E7: 34989 | F7: 34989
A8: Communes | B8: 34955 | C8: 34945 | D8: 34935 | E8: 34875 | F8: 34875
A9: dont : France métropolitaine | B9: 34826 | C9: 34816 | D9: 34806 | E9: 34746 | F9: 34746
A10: Outre-mer | B10: 129 | C10: 129 | D10: 129 | E10: 129 | F10: 129
A12: Conseils départementaux (a) | B12: 95 | C12: 95 | D12: 95 | E12: 95 | F12: 95
A13: dont : France métropolitaine | B13: 93 | C13: 93 | D13: 93 | E13: 93 | F13: 93
A14: Outre-mer | B14: 2 | C14: 2 | D14: 2 | E14: 2 | F14: 2
A16: Conseils régionaux | B16: 14 | C16: 14 | D16: 14 | E16: 14 | F16: 14
A17: dont : France métropolitaine | B17: 12 | C17: 12 | D17: 12 | E17: 12 | F17: 12
A18: Outre-mer | B18: 2 | C18: 2 | D18: 2 | E18: 2 | F18: 2
A20: Collectivités à statut particulier | B20: 5 | C20: 5 | D20: 5 | E20: 5 | F20: 5
... A28: Syndicats | B28: 8882 | C28: 8777 | D28: 8629 | E28: 8322 | F28: 8113
A29: Source : Insee, Code officiel géographique ; DGCL, Banatic.
A30: (a) Depuis 2021, le nombre de conseils départementaux est passé de 96 à 95, en lien avec la création de la Collectivité européenne d'Alsace, département de droit commun, par le décret n° 2019-142 du 27 février 2019 portant regroupement des départements du Bas-Rhin et du Haut-Rhin.

Sheet 2.3a Com
A1: 2.3a Les communes par taille
A3: Nombre de communes et population municipale au 1er janvier 2026, selon la taille des communes
A5: Taille des communes | B5: France métropolitaine | D5: DOM | F5: France métropolitaine + DOM
B6: Nombre de communes | C6: Population municipale | D6: Nombre de communes | E6: Population municipale | F6: Nombre de communes | G6: Population municipale
A7: Moins de 50 habitants | B7: 901 | C7: 30853 | D7: 0 | E7: 0 | F7: =B7+D7 -> 901 | G7: =C7+E7 -> 30853
A8: 50 à 99 habitants | B8: 2499 | C8: 189337 | D8: 0 | E8: 0 | F8: =B8+D8 -> 2499 | G8: =C8+E8 -> 189337
A9: 100 à 199 habitants | B9: 5401 | C9: 795935 | D9: 2 | E9: 309 | F9: =B9+D9 -> 5403 | G9: =C9+E9 -> 796244
A10: 200 à 299 habitants | B10: 4199 | C10: 1034195 | D10: 1 | E10: 277 | F10: =B10+D10 -> 4200 | G10: =C10+E10 -> 1034472
A11: 300 à 399 habitants | B11: 3087 | C11: 1069847 | D11: 0 | E11: 0 | F11: =B11+D11 -> 3087 | G11: =C11+E11 -> 1069847
A12: 400 à 499 habitants | B12: 2165 | C12: 967793 | D12: 1 | E12: 487 | F12: =B12+D12 -> 2166 | G12: =C12+E12 -> 968280
A13: 500 à 699 habitants | B13: 3528 | C13: 2087580 | D13: 1 | E13: 640 | F13: =B13+D13 -> 3529 | G13: =C13+E13 -> 2088220
A14: 700 à 999 habitants | B14: 3057 | C14: 2552539 | D14: 2 | E14: 1860 | F14: =B14+D14 -> 3059 | G14: =C14+E14 -> 2554399
A15: 1 000 à 1 499 habitants | B15: 2943 | C15: 3583011 | D15: 3 | E15: 4248 | F15: =B15+D15 -> 2946 | G15: =C15+E15 -> 3587259
A16: 1 500 à 1 999 habitants | B16: 1569 | C16: 2704824 | D16: 7 | E16: 11717 | F16: =B16+D16 -> 1576 | G16: =C16+E16 -> 2716541
A17: 2 000 à 2 499 habitants | B17: 1057 | C17: 2356264 | D17: 1 | E17: 2189 | F17: =B17+D17 -> 1058 | G17: =C17+E17 -> 2358453
A18: 2 500 à 2 999 habitants | B18: 669 | C18: 1827822 | D18: 4 | E18: 11166 | F18: =B18+D18 -> 673 | G18: =C18+E18 -> 1838988
... A32: 300 000 habitants et plus | B32: 7 | C32: 5019475 | D32: 0 | E32: 0 | F32: =B32+D32 -> 7 | G32: =C32+E32 -> 5019475
A33: Total | B33: =SUM(B7:B32) -> 34746 | C33: =SUM(C7:C32) -> 66165815 | D33: =SUM(D7:D32) -> 129 | E33: =SUM(E7:E32) -> 2184983 | F33: =SUM(F7:F32) -> 34875 | G33: =SUM(G7:G32) -> 68350798
A34: Source : Insee, Recensement de la population. Population municipale en vigueur en 2026 (millésimée 2023)
A35: Champ : France métropolitaine + DOM.
A36: Le département de Mayotte a été recensé en 2017.

Sheet 2.3b Rep com
A1: 2.3b Les communes par taille
A3: Répartition (en % et en % cumulés) du nombre de communes et de la population municipale au 1er janvier 2026, selon la taille des communes
A5: Taille des communes | B5: Nombre de communes | C5: Population | D5: Taille des communes | F5: Nombre de communes | G5: Population | K5: Communes | L5: Population
B6: En % | F6: En % cumulés | K6: 0 | L6: 0
A7: Moins de 50 habitants | B7: =+'2.3a Com'!F7/'2.3a Com'!F$33 -> 0.025835125 | C7: =+'2.3a Com'!G7/'2.3a Com'!G$33 -> 0.00045139195 | D7: Moins de 50 habitants | F7: =+B7 -> 0.025835125 | G7: =+C7 -> 0.00045139195 | I7: 50 | J7: < 50 h. | K7: =+F7 -> 0.025835125 | L7: =+G7 -> 0.00045139195
A8: 50 à 99 habitants | B8: =+'2.3a Com'!F8/'2.3a Com'!F$33 -> 0.071655914 | C8: =+'2.3a Com'!G8/'2.3a Com'!G$33 -> 0.0027700774 | D8: Moins de 100 habitants | F8: =+F7+B8 -> 0.097491039 | G8: =+G7+C8 -> 0.0032214693 | I8: 100 | J8: < 100 h. | K8: =+F8 -> 0.097491039 | L8: =+G8 -> 0.0032214693
A9: 100 à 199 habitants | B9: =+'2.3a Com'!F9/'2.3a Com'!F$33 -> 0.15492473 | C9: =+'2.3a Com'!G9/'2.3a Com'!G$33 -> 0.011649374 | D9: Moins de 200 habitants | F9: =+F8+B9 -> 0.25241577 | G9: =+G8+C9 -> 0.014870843 | I9: 200 | J9: < 200 h. | K9: =+F9 -> 0.25241577 | L9: =+G9 -> 0.014870843
A10: 200 à 299 habitants | B10: =+'2.3a Com'!F10/'2.3a Com'!F$33 -> 0.12043011 | C10: =+'2.3a Com'!G10/'2.3a Com'!G$33 -> 0.015134746 | D10: Moins de 300 habitants | F10: =+F9+B10 -> 0.37284588 | G10: =+G9+C10 -> 0.03000559 | I10: 300 | J10: < 300 h. | K10: =+F10 -> 0.37284588 | L10: =+G10 -> 0.03000559
A11: 300 à 399 habitants | B11: =+'2.3a Com'!F11/'2.3a Com'!F$33 -> 0.088516129 | C11: =+'2.3a Com'!G11/'2.3a Com'!G$33 -> 0.015652297 | D11: Moins de 400 habitants | F11: =+F10+B11 -> 0.46136201 | G11: =+G10+C11 -> 0.045657887 | I11: 400 | J11: < 400 h. | K11: =+F11 -> 0.46136201 | L11: =+G11 -> 0.045657887
A12: 400 à 499 habitants | B12: =+'2.3a Com'!F12/'2.3a Com'!F$33 -> 0.062107527 | C12: =+'2.3a Com'!G12/'2.3a Com'!G$33 -> 0.014166331 | D12: Moins de 500 habitants | F12: =+F11+B12 -> 0.52346953 | G12: =+G11+C12 -> 0.059824217 | I12: 500 | J12: < 500 h. | K12: =+F12 -> 0.52346953 | L12: =+G12 -> 0.059824217
A13: 500 à 699 habitants | B13: =+'2.3a Com'!F13/'2.3a Com'!F$33 -> 0.10118996 | C13: =+'2.3a Com'!G13/'2.3a Com'!G$33 -> 0.030551509 | D13: Moins de 700 habitants | F13: =+F12+B13 -> 0.6246595 | G13: =+G12+C13 -> 0.090375726 | I13: 700 | J13: < 700 h. | K13: =+F13 -> 0.6246595 | L13: =+G13 -> 0.090375726
A14: 700 à 999 habitants | B14: =+'2.3a Com'!F14/'2.3a Com'!F$33 -> 0.087713262 | C14: =+'2.3a Com'!G14/'2.3a Com'!G$33 -> 0.037371897 | D14: Moins de 1 000 habitants | F14: =+F13+B14 -> 0.71237276 | G14: =+G13+C14 -> 0.12774762 | I14: 1000 | J14: < 1 000 h. | K14: =+F14 -> 0.71237276 | L14: =+G14 -> 0.12774762
A15: 1 000 à 1 499 habitants | B15: =+'2.3a Com'!F15/'2.3a Com'!F$33 -> 0.084473118 | C15: =+'2.3a Com'!G15/'2.3a Com'!G$33 -> 0.05248306 | D15: Moins de 1 500 habitants | F15: =+F14+B15 -> 0.79684588 | G15: =+G14+C15 -> 0.18023068 | I15: 1500 | J15: < 1 500 h. | K15: =+F15 -> 0.79684588 | L15: =+G15 -> 0.18023068
A16: 1 500 à 1 999 habitants | B16: =+'2.3a Com'!F16/'2.3a Com'!F$33 -> 0.045189964 | C16: =+'2.3a Com'!G16/'2.3a Com'!G$33 -> 0.039744101 | D16: Moins de 2 000 habitants | F16: =+F15+B16 -> 0.84203584 | G16: =+G15+C16 -> 0.21997478 | I16: 2000 | J16: < 2 000 h. | K16: =+F16 -> 0.84203584 | L16: =+G16 -> 0.21997478
A17: 2 000 à 2 499 habitants | B17: =+'2.3a Com'!F17/'2.3a Com'!F$33 -> 0.030336918 | C17: =+'2.3a Com'!G17/'2.3a Com'!G$33 -> 0.034505128 | D17: Moins de 2 500 habitants | F17: =+F16+B17 -> 0.87237276 | G17: =+G16+C17 -> 0.25447991 | I17: 2500 | J17: < 2 500 h. | K17: =+F17 -> 0.87237276 | L17: =+G17 -> 0.25447991
A18: 2 500 à 2 999 habitants | B18: =+'2.3a Com'!F18/'2.3a Com'!F$33 -> 0.019297491 | C18: =+'2.3a Com'!G18/'2.3a Com'!G$33 -> 0.026905143 | D18: Moins de 3 000 habitants | F18: =+F17+B18 -> 0.89167025 | G18: =+G17+C18 -> 0.28138505 | I18: 3000 | J18: < 3 000 h. | K18: =+F18 -> 0.89167025 | L18: =+G18 -> 0.28138505
A19: 3 000 à 3 499 habitants | B19: =+'2.3a Com'!F19/'2.3a Com'!F$33 -> 0.01502509 | C19: =+'2.3a Com'!G19/'2.3a Com'!G$33 -> 0.024787918 | D19: Moins de 3 500 habitants | F19: =+F18+B19 -> 0.90669534 | G19: =+G18+C19 -> 0.30617297 | I19: 3500 | J19: < 3 500 h. | K19: =+F19 -> 0.90669534 | L19: =+G19 -> 0.30617297
... A31: 200 000 à 299 999 habitants | B31: =+'2.3a Com'!F31/'2.3a Com'!F$33 -> 0.00011469534 | C31: =+'2.3a Com'!G31/'2.3a Com'!G$33 -> 0.015082457 | D31: Moins de 300 000 habitants | F31: =+F30+B31 -> 0.99979928 | G31: =+G30+C31 -> 0.92656304 | I31: 300000 | J31: < 300 000 h. | K31: =+F31 -> 0.99979928 | L31: =+G31 -> 0.92656304
A32: 300 000 habitants et plus | B32: =+'2.3a Com'!F32/'2.3a Com'!F$33 -> 0.00020071685 | C32: =+'2.3a Com'!G32/'2.3a Com'!G$33 -> 0.073436963 | D32: Toutes tailles confondues | F32: =+F31+B32 -> 1 | G32: =+G31+C32 -> 1 | J32: Ensemble | K32: 1 | L32: 1
A33: Total | B33: =+'2.3a Com'!F33/'2.3a Com'!F$33 -> 1 | C33: =+'2.3a Com'!G33/'2.3a Com'!G$33 -> 1 | D33: Toutes tailles confondues | F33: 1 | G33: 1
A34: Source : Insee, Recensement de la population.
A35: Champ : France métropolitaine + DOM.
A36: Le département de Mayotte a été recensé en 2017.
A37: Lecture : 2,6 % des communes ont moins de 50 habitants et 7,2 % des communes ont entre 50 et 99 habitants. Ces dernières regroupent 0,3 % de la population. Cumulées, les communes de moins de 100 habitants regroupent 0,3 % de la population et représentent 9,7 % des communes.
A39: Répartition (en % cumulés) du nombre de communes et de la population municipale au 1er janvier 2026, selon la taille des communes
A61: Source : Insee, Recensement de la population.
A62: Champ : France métropolitaine + DOM.
A63: Lecture : Les communes de moins de 3 000 habitants regroupent 89,2 % des communes ; elles regroupent 28,1 % de la population.

Sheet 2.4 Com +100
A1: 2.4 Les communes de plus de 100 000 habitants
A3: Les communes de plus de 100 000 habitants
A4: (en nombre d'habitants)
A6: Rang | B6: Commune (n° du département) | C6: Population municipale | E6: Taux d'évolution sur 6 ans
C7: 2020 (millésimée 2017) | D7: 2026 (millésimée 2023)
A8: 1 | B8: Paris (75) | C8: 2187526 | D8: 2103778 | E8: -0.038284345
A9: 2 | B9: Marseille (13) | C9: 863310 | D9: 886040 | E9: 0.026328897
A10: 3 | B10: Lyon (69) | C10: 516092 | D10: 519127 | E10: 0.0058807344
A11: 4 | B11: Toulouse (31) | C11: 479553 | D11: 514819 | E11: 0.073539317
A12: 5 | B12: Nice (06) | C12: 340017 | D12: 357737 | E12: 0.052115041
A13: 6 | B13: Nantes (44) | C13: 309346 | D13: 327734 | E13: 0.059441531
A14: 7 | B14: Montpellier (34) | C14: 285121 | D14: 310240 | E14: 0.088099438
A15: 8 | B15: Strasbourg (67) | C15: 280966 | D15: 293771 | E15: 0.045574909
A16: 9 | B16: Bordeaux (33) | C16: 254436 | D16: 267991 | E16: 0.053274694
A17: 10 | B17: Lille (59) | C17: 232787 | D17: 238246 | E17: 0.023450622
A18: 11 | B18: Rennes (35) | C18: 216815 | D18: 230890 | E18: 0.064917095
A19: 12 | B19: Toulon (83) | C19: 171953 | D19: 179116 | E19: 0.041656732
... A49: 42 | B49: Nancy (54) | C49: 104286 | D49: 103671 | E49: -0.0058972441
A50: Source : Insee, Recensement de la population.
A51: Champ : France métropolitaine + DOM.

Sheet 2.5a EPCI
A1: 2.5a Les groupements de collectivités territoriales
A3: Nombre de groupements de communes à fiscalité propre
A4: Au 1er janvier | B4: 2022 | C4: 2023 | D4: 2024 | E4: 2025 | F4: 2026 | G4: Variation 2026-2025
A5: Métropoles | B5: 21 | C5: 21 | D5: 21 | E5: 21 | F5: 21 | G5: 0
A6: Communautés urbaines (CU) | B6: 14 | C6: 14 | D6: 14 | E6: 14 | F6: 14 | G6: 0
A7: Communautés d'agglomération (CA) | B7: 227 | C7: 227 | D7: 229 | E7: 230 | F7: 230 | G7: 0
A8: Communautés de communes (CC) | B8: 992 | C8: 992 | D8: 990 | E8: 989 | F8: 987 | G8: -2
A9: Nombre d'EPCI à fiscalité propre | B9: 1254 | C9: 1254 | D9: 1254 | E9: 1254 | F9: 1252 | G9: -2
A10: Métropole de Lyon | B10: 1 | C10: 1 | D10: 1 | E10: 1 | F10: 1 | G10: 0
A11: Nombre de communes regroupées(a) | B11: 34951 | C11: 34941 | D11: 34931 | E11: 34871 | F11: 34871 | G11: 0
A12: Nombre de communes isolées | B12: 4 | C12: 4 | D12: 4 | E12: 4 | F12: 4 | G12: 0
A13: Nombre total de communes | B13: 34955 | C13: 34945 | D13: 34935 | E13: 34875 | F13: 34875 | G13: 0
A14: EPCI à fiscalité professionnelle unique :
A15: Nombre de groupements | B15: 1084 | C15: 1090 | D15: 1093 | E15: 1094 | F15: 1096 | G15: 2
A16: Nombre de communes regroupées(a) | B16: 30231 | C16: 30329 | D16: 30446 | E16: 30418 | F16: 30449 | G16: 31
A17: Sources : DGCL, Banatic ; Insee, Recensements de la population.
A18: Champ : France métropolitaine + DOM.
A19: (a) Y compris les communes de la métropole de Lyon
A22: Population(a) regroupée dans des groupements à fiscalité propre | K22: Pour chapitre 1 :
A23: Au 1er janvier | B23: 2022 | C23: 2023 | D23: 2024 | E23: 2025 | F23: 2026 | G23: Évolution 2026 / 2025
A24: Métropoles | B24: 18273350 | C24: 18331597 | D24: 18420395 | E24: 18522621 | F24: 18631120 | G24: 0.0058576483 | J24: Métropoles (a) | K24: =+(F24+F29)/1000000 -> 20.083081
A25: Communauté urbaines (CU) | B25: 3138765 | C25: 3146023 | D25: 3157842 | E25: 3175191 | F25: 3190068 | G25: 0.0046853874 | J25: Communautés urbaines (CU) | K25: =+F25/1000000 -> 3.190068
A26: Communautés d'agglomération (CA) | B26: 23777483 | C26: 23835713 | D26: 24081689 | E26: 24293546 | F26: 24481368 | G26: 0.0077313538 | J26: Communautés d'agglomération (CA) | K26: =+F26/1000000 -> 24.481368
A27: Communautés de communes (CC) | B27: 21867973 | C27: 21898670 | D27: 21776996 | E27: 21776752 | F27: 21795879 | G27: 0.00087832198 | J27: Communautés de communes (CC) | K27: =+F27/1000000 -> 21.795879
A28: Population totale des EPCI à fiscalité propre | B28: 67057571 | C28: 67212003 | D28: 67436922 | E28: 67768110 | F28: =SUM(F24:F27) -> 68098435 | G28: 0.0048743428 | J28: Communes isolées | K28: =+F31/1000000 -> 0.006604
A29: Métropole de Lyon | B29: 1428062 | C29: 1432690 | D29: 1439981 | E29: 1449118 | F29: 1451961 | G29: 0.001961883 | J29: (a) Y compris la métropole de Lyon.
A30: Population totale regroupée | B30: 68485633 | C30: 68644693 | D30: 68876903 | E30: 69217228 | F30: 69550396 | G30: 0.0048133681
A31: Population totale des communes isolées | B31: 6460 | C31: 6509 | D31: 6557 | E31: 6612 | F31: 6604 | G31: -0.0012099214
A32: Population regroupée des EPCI à FPU | B32: 65733519 | C32: 65994743 | D32: 66486964 | E32: 66834214 | F32: 67197711 | G32: 0.0054387862
A33: Sources : DGCL, Banatic ; Insee, Recensements de la population.
A34: Champ : France métropolitaine + DOM.
A35: (a) Population totale, en vigueur au 1er janvier de chaque année, des communes composant les groupements.
A38: Nombre de syndicats(a)
A39: Au 1er janvier | B39: 2022 | C39: 2023 | D39: 2024 | E39: 2025 | F39: 2026 | G39: Variation 2026-2025
A40: Syndicats intercommunaux à vocation unique (SIVU) | B40: 4738 | C40: 4637 | D40: 4533 | E40: 4307 | F40: 4049 | G40: -258
A41: Syndicats intercommunaux à vocation multiple (SIVOM) | B41: 1214 | C41: 1207 | D41: 1199 | E41: 1172 | F41: 1233 | G41: 61
A42: Etablissements publics territoriaux (EPT) | B42: 11 | C42: 11 | D42: 11 | E42: 11 | F42: 11 | G42: 0
A43: Syndicats mixtes | B43: 2770 | C43: 2771 | D43: 2739 | E43: 2686 | F43: 2676 | G43: -10
A44: Pôles métropolitains | B44: 25 | C44: 26 | D44: 25 | E44: 24 | F44: 23 | G44: -1
A45: Pôles d'équilibre territorial et rural (PETR) | B45: 124 | C45: 125 | D45: 122 | E45: 122 | F45: 121 | G45: -1
...

Sheet 2.5b-carte
A1: 2.5b Les groupements de collectivités territoriales à fiscalité propre au 1er janvier 2026

Sheet 2.6 GFP taille
A1: 2.6 Les groupements de communes à fiscalité propre par taille
A3: Répartition des groupements de communes à fiscalité propre par taille démographique au 1er janvier 2026
A4: En nombre de groupements comportant(a): | B4: Métropoles | C4: CU | D4: CA | E4: CC | G4: EPCI à FP
E5: FPU | F5: FA | G5: Total | H5: dont FPU
A6: moins de 5000 habitants | E6: 4 | F6: 3 | G6: 7 | H6: 4
A7: de 5 000 à 15 000 habitants | E7: 252 | F7: 91 | G7: 343 | H7: 252
A8: de 15 000 à 30 000 habitants | D8: 2 | E8: 366 | F8: 51 | G8: 419 | H8: 368
A9: de 30 000 à 50 000 habitants | D9: 16 | E9: 168 | F9: 11 | G9: 195 | H9: 184
A10: de 50 000 à 100 000 habitants | C10: 2 | D10: 115 | E10: 37 | F10: 1 | G10: 155 | H10: 154
A11: de 100 000 à 300 000 habitants | B11: 4 | C11: 9 | D11: 92 | E11: 3 | G11: 108 | H11: 108
A12: 300 000 habitants et plus | B12: 17 | C12: 3 | D12: 5 | G12: 25 | H12: 25
A13: Total | B13: 21 | C13: 14 | D13: 230 | E13: 830 | F13: 157 | G13: 1252 | H13: 1095
A14: Nombre de communes regroupées | B14: 911 | C14: 659 | D14: 7608 | E14: 21213 | F14: 4422 | G14: 34 871(b) | H14: 30 449(b)
A15: Population totale (en millions d'habitants)(a) | B15: 18.63112 | C15: 3.190068 | D15: 24.481368 | E15: 19.443194 | F15: 2.352685 | G15: 69,6(b) | H15: 67,2(b)
A16: Sources : DGCL, Banatic ; Insee, Recensement de la population.
A17: Champ : France métropolitaine + DOM.
A18: CU : communauté urbaine ; CA : communauté d'agglomération ; CC : communauté de communes ; FPU : fiscalité professionnelle unique ; FA : fiscalité additionnelle.
A19: (a) Population totale en vigueur en 2026 (millésimée 2023).
A20: (b) Bien qu'elle soit une collectivité territoriale, la métropole de Lyon est ici prise en compte dans le nombre de communes et dans le nombre d’habitants couverts par un EPCI à fiscalité propre car elle en exerce les compétences.
A23: Population moyenne par nature juridique
A24: (en nombre moyen d'habitants)
A25: Au 1er janvier | B25: 2022 | C25: 2023 | D25: 2024 | E25: 2025 | F25: 2026
A26: Communautés de communes (CC) | B26: 22044 | C26: 22075 | D26: 21997 | E26: 22019 | F26: 22083
A27: Communautés d'agglomération (CA) | B27: 104747 | C27: 105003 | D27: 105160 | E27: 105624 | F27: 106441
A28: Communautés urbaines (CU) | B28: 224198 | C28: 224716 | D28: 225560 | E28: 226799 | F28: 227862
A29: Métropoles | B29: 870160 | C29: 872933 | D29: 877162 | E29: 882030 | F29: 887196
A30: Métropole de Lyon | B30: 1428062 | C30: 1432690 | D30: 1439981 | E30: 1449118 | F30: 1451961
A31: Ensemble | B31: 54570 | C31: 54697 | D31: 54882 | E31: 55153 | F31: 55507
A32: Sources : DGCL, Banatic ; Insee, Recensement de la population.
A33: Champ : France métropolitaine + DOM.
A36: Population moyenne des syndicats par nature juridique
A37: (en nombre moyen d'habitants)
A38: Au 1er janvier | B38: 2022 | C38: 2023 | D38: 2024 | E38: 2025 | F38: 2026
A39: Syndicats intercommunaux à vocation unique (SIVU) | B39: 12908 | C39: 12871 | D39: 12793 | E39: 12549 | F39: 12703
A40: Syndicats intercommunaux à vocation multiple (SIVOM) | B40: 14184 | C40: 14137 | D40: 14183 | E40: 14724 | F40: 14919
A41: Etablissements publics territoriaux (EPT) | B41: 451160 | C41: 452160 | D41: 454847 | E41: 457651 | F41: 461000
A42: Syndicats mixtes | B42: 221862 | C42: 227704 | D42: 226595 | E42: 196833 | F42: 195947
A43: Pôles métropolitains | B43: 611266 | C43: 605935 | D43: 550160 | E43: 562649 | F43: 549890
A44: Pôles d'équilibre territorial et rural (PETR) | B44: 86137 | C44: 86056 | D44: 85439 | E44: 85385 | F44: 86099
A45: Ensemble | B45: 81445 | C45: 84239 | D45: 83998 | E45: 75577 | F45: 76705
...

Sheet 2.7a met CU
A1: 2.7a Les principaux groupements de communes à fiscalité propre
A3: Les 21 métropoles au 1er janvier 2026
A4: N° du département | B4: Dénomination | D4: Nombre total de communes | E4: Population totale(a)
A5: 75 | B5: Métropole du Grand Paris | D5: 130 | E5: 7190408
A6: 13 | B6: Métropole d'Aix-Marseille-Provence | D6: 92 | E6: 1961169
A7: 59 | B7: Métropole Européenne de Lille | D7: 95 | E7: 1206167
A8: 33 | B8: Bordeaux Métropole | D8: 28 | E8: 865747
A9: 31 | B9: Toulouse Métropole | D9: 37 | E9: 851402
A10: 44 | B10: Nantes Métropole | D10: 24 | E10: 700869
A11: 06 | B11: Métropole Nice Côte d'Azur | D11: 51 | E11: 579965
A12: 34 | B12: Montpellier Méditerranée Métropole | D12: 31 | E12: 528988
A13: 67 | B13: Eurométropole de Strasbourg | D13: 33 | E13: 527727
A14: 76 | B14: Métropole Rouen Normandie | D14: 71 | E14: 509949
A15: 35 | B15: Rennes Métropole | D15: 43 | E15: 489359
A16: 38 | B16: Grenoble-Alpes-Métropole | D16: 49 | E16: 456596
... A25: 29 | B25: Brest Métropole | D25: 8 | E25: 219395
B26: Total | D26: =SUM(D5:D25) -> 911 | E26: =SUM(E5:E25) -> 18631120
A27: Source : DGCL, Banatic ; Insee, Recensement de la population.
A28: (a) Population totale en vigueur en 2026 (millésimée 2023).
A30: Les 14 communautés urbaines au 1er janvier 2026
A31: N° du département | B31: Dénomination | D31: Nombre total de communes | E31: Population totale(a)
A32: 78 | B32: CU Grand Paris Seine et Oise | D32: 73 | E32: 442427
A33: 49 | B33: CU Angers Loire Métropole | D33: 29 | E33: 319672
A34: 51 | B34: CU du Grand Reims | D34: 143 | E34: 303136
A35: 14 | B35: CU Caen la Mer | D35: 48 | E35: 285877
A36: 66 | B36: CU Perpignan Méditerranée Métropole | D36: 37 | E36: 283665
A37: 76 | B37: Le Havre Seine Métropole | D37: 54 | E37: 270812
A38: 72 | B38: CU Le Mans Métropole | D38: 20 | E38: 214788
A39: 87 | B39: CU Limoges Métropole | D39: 20 | E39: 210901
A40: 86 | B40: CU du Grand Poitiers | D40: 40 | E40: 202101
A41: 25 | B41: CU Grand Besançon Métropole | D41: 67 | E41: 201908
A42: 59 | B42: CU de Dunkerque | D42: 17 | E42: 194080
A43: 62 | B43: CU d'Arras | D43: 46 | E43: 111970
... A45: 61 | B45: CU d'Alençon | D45: 31 | E45: 56863
B46: Total | D46: =SUM(D32:D45) -> 659 | E46: =SUM(E32:E45) -> 3190068
A47: Source : DGCL, Banatic ; Insee, Recensement de la population.
A48: (a) Population totale en vigueur en 2026 (millésimée 2023).

Sheet 2.7b CA
A1: 2.7b Les principaux groupements de communes à fiscalité propre
A3: Les 97 communautés d'agglomération de plus de 100 000 habitants au 1er janvier 2026
A4: N° du département | B4: Dénomination | C4: Nombre total de communes | D4: Population totale(a)
A5: 95 | B5: CA Roissy Pays de France | C5: 42 | D5: 369572
A6: 91 | B6: CA Grand Paris Sud Seine Essonne Sénart | C6: 23 | D6: 367505
A7: 78 | B7: CA Saint Germain Boucles de Seine | C7: 19 | D7: 353616
A8: 64 | B8: CA du Pays Basque | C8: 158 | D8: 338563
A9: 91 | B9: CA Communauté Paris-Saclay | C9: 27 | D9: 330599
A10: 95 | B10: CA Val Parisis | C10: 15 | D10: 293108
A11: 62 | B11: CA de Béthune-Bruay, Artois-Lys Romane | C11: 100 | D11: 278237
A12: 68 | B12: CA Mulhouse Alsace Agglomération | C12: 39 | D12: 278063
A13: 78 | B13: CA Versailles Grand Parc (CAVGP) | C13: 18 | D13: 275722
A14: 30 | B14: CA de Nîmes Métropole | C14: 39 | D14: 268103
A15: 62 | B15: CA de Lens - Liévin | C15: 36 | D15: 243876
A16: 78 | B16: CA de Saint Quentin en Yvelines | C16: 12 | D16: 237581
... A62: 83 | B62: Estérel Côte d'Azur Agglomération | C62: 5 | D62: 125439
A63: N° du département | B63: Dénomination | C63: Nombre total de communes | D63: Population totale(a)
A64: 59 | B64: CA Maubeuge Val de Sambre | C64: 43 | D64: 123534
A65: 08 | B65: Ardenne Métropole | C65: 57 | D65: 122709
A66: 53 | B66: CA Laval Agglomération | C66: 34 | D66: 119115
A67: 28 | B67: CA Agglo du Pays de Dreux | C67: 81 | D67: 118398
A68: 71 | B68: CA Le Grand Chalon | C68: 51 | D68: 117552
A69: 83 | B69: Dracénie Provence Verdon Agglomération | C69: 23 | D69: 117200
A70: 11 | B70: CA Carcassonne Agglo | C70: 83 | D70: 116840
A71: 972 | B71: CA de l'Espace Sud de la Martinique | C71: 12 | D71: 116235
A72: 27 | B72: CA Evreux Portes de Normandie | C72: 74 | D72: 115980
A73: 42 | B73: Loire Forez Agglomération (LFA) | C73: 84 | D73: 115780
A74: 68 | B74: CA Colmar Agglomération | C74: 20 | D74: 115593
A75: 38 | B75: CA Porte de l'Isère (CAPI) | C75: 22 | D75: 114874
... A102: 38 | B102: CA du Pays Voironnais | C102: 31 | D102: 100035
A103: Source : DGCL, Banatic ; Insee, Recensement de la population.
A104: Champ : France métropolitaine + DOM.
A105: (a) Population totale en vigueur en 2026 (millésimée 2023).

Sheet 2.7c CC
A1: 2.7c Les principaux groupements de communes à fiscalité propre
A3: Les 41 communautés de communes de plus de 50 000 habitants au 1er janvier 2026
A4: N° du département | B4: Dénomination | C4: Régime fiscal | D4: Nombre total de communes | E4: Population totale(a)
A5: 38 | B5: CC Le Grésivaudan | C5: FPU | D5: 43 | E5: 107361
A6: 973 | B6: CC de l'Ouest Guyanais | C6: FPU | D6: 8 | E6: 102407
A7: 59 | B7: CC Pévèle-Carembault | C7: FPU | D7: 38 | E7: 101976
A8: 56 | B8: CC Auray Quiberon Terre Atlantique | C8: FPU | D8: 24 | E8: 93712
A9: 01 | B9: CC de la Plaine de l'Ain | C9: FPU | D9: 53 | E9: 85650
A10: 38 | B10: CC Les Balcons du Dauphiné | C10: FPU | D10: 47 | E10: 80904
A11: 40 | B11: CC Maremne Adour Côte Sud | C11: FPU | D11: 23 | E11: 74286
A12: 44 | B12: CC du Pays d'Ancenis | C12: FPU | D12: 20 | E12: 71962
A13: 38 | B13: CC Entre Bièvre et Rhône | C13: FPU | D13: 37 | E13: 71718
A14: 17 | B14: CC de la Haute Saintonge | C14: FA | D14: 129 | E14: 71010
A15: 44 | B15: CC d'Erdre et Gesvres | C15: FPU | D15: 12 | E15: 70330
A16: 38 | B16: CC Les Vals du Dauphiné | C16: FPU | D16: 36 | E16: 66598
... A45: 74 | B45: CC du Genevois | C45: FPU | D45: 17 | E45: 50728
A46: Source : DGCL, Banatic ; Insee, Recensement de la population.
A47: Champ : France métropolitaine + DOM.
A48: (a) Population totale en vigueur en 2026 (millésimée 2023).

Sheet Pour Dépliant 1
B3: 68,4 millions d'habitants en France au 1er janvier 2026, répartis dans 34 875 communes, 101 départements et 18 régions.
B4: Répartition des communes selon leur taille
B5: Taille de la commune | C5: Nombre de communes | D5: Part de la population
B6: De 0 à 200 habitants | C6: 0.25241577 | D6: 0.014870843
B7: De 200 à 500 habitants | C7: 0.27105376 | D7: 0.044953374
B8: De 500 à 2 000 habitants | C8: 0.31856631 | D8: 0.16015057
B9: De 2 000 à 5 000 habitants | C9: 0.093419355 | D9: 0.14719212
B10: De 5 000 à 10 000 habitants | C10: 0.034494624 | D10: 0.12207825
B11: De 10 000 à 20 000 habitants | C11: 0.016172043 | D11: 0.11275936
B12: De 20 000 à 50 000 habitants | C12: 0.010035842 | D12: 0.156364
B13: De 50 000 à 100 000 habitants | C13: 0.0026379928 | D13: 0.090550135
B14: 100 000 habitants ou plus | C14: 0.0012043011 | D14: 0.15108135
B16: Taille de la commune | C16: Nombre de communes | D16: Part de la population
B17: Moins de 200 habitants | C17: =+C6 -> 0.25241577 | D17: =+D6 -> 0.014870843
B18: Moins de 500 habitants | C18: =+C17+C7 -> 0.52346953 | D18: =+D17+D7 -> 0.059824217
B19: Moins de 2 000 habitants | C19: =+C18+C8 -> 0.84203584 | D19: =+D18+D8 -> 0.21997478
B20: Moins de 5 000 habitants | C20: =+C19+C9 -> 0.9354552 | D20: =+D19+D9 -> 0.36716691
B21: Moins de 10 000 habitants | C21: =+C20+C10 -> 0.96994982 | D21: =+D20+D10 -> 0.48924516
B22: Moins de 20 000 habitants | C22: =+C21+C11 -> 0.98612186 | D22: =+D21+D11 -> 0.60200452
B23: Moins de 50 000 habitants | C23: =+C22+C12 -> 0.99615771 | D23: =+D22+D12 -> 0.75836851
B24: Moins de 100 000 habitants | C24: =+C23+C13 -> 0.9987957 | D24: =+D23+D13 -> 0.84891865
B25: Toutes tailles confondues | C25: 1 | D25: 1
A27: Source : Insee, Recensement de la population. Population municipale en vigueur en année N (millésimée année N-3)
